#总结记录/工作记录 

- 将track3下的run_test.sh中的测试路径直接换成3stereo的测试集, 然而报错如下

```
Traceback (most recent call last):
  File "local/segmentation/score_sad.py", line 452, in <module>
    main()
  File "local/segmentation/score_sad.py", line 436, in main
    per_domain_metrics = score_recordings(
  File "local/segmentation/score_sad.py", line 309, in score_recordings
    domain_metrics[metric_name] = sum_metrics(
  File "local/segmentation/score_sad.py", line 238, in sum_metrics
    cls = metrics[0].__class__
IndexError: tuple index out of range
```

- 一直往回debug